Traceback (most recent call last):
  File "/home/rvarm1/.conda/envs/torchtune-v0.1.0/bin/tune", line 8, in <module>
    sys.exit(main())
             ^^^^^^
  File "/home/rvarm1/.conda/envs/torchtune-v0.1.0/lib/python3.11/site-packages/torchtune/_cli/tune.py", line 49, in main
    parser.run(args)
  File "/home/rvarm1/.conda/envs/torchtune-v0.1.0/lib/python3.11/site-packages/torchtune/_cli/tune.py", line 43, in run
    args.func(args)
  File "/home/rvarm1/.conda/envs/torchtune-v0.1.0/lib/python3.11/site-packages/torchtune/_cli/run.py", line 179, in _run_cmd
    self._run_single_device(args)
  File "/home/rvarm1/.conda/envs/torchtune-v0.1.0/lib/python3.11/site-packages/torchtune/_cli/run.py", line 93, in _run_single_device
    runpy.run_path(str(args.recipe), run_name="__main__")
  File "<frozen runpy>", line 291, in run_path
  File "<frozen runpy>", line 98, in _run_module_code
  File "<frozen runpy>", line 88, in _run_code
  File "/home/rvarm1/.conda/envs/torchtune-v0.1.0/lib/python3.11/site-packages/recipes/generate.py", line 141, in <module>
    sys.exit(main())
             ^^^^^^
  File "/home/rvarm1/.conda/envs/torchtune-v0.1.0/lib/python3.11/site-packages/torchtune/config/_parse.py", line 47, in wrapper
    yaml_args, cli_args = parser.parse_known_args()
                          ^^^^^^^^^^^^^^^^^^^^^^^^^
  File "/home/rvarm1/.conda/envs/torchtune-v0.1.0/lib/python3.11/site-packages/torchtune/utils/argparse.py", line 55, in parse_known_args
    config = OmegaConf.load(namespace.config)
             ^^^^^^^^^^^^^^^^^^^^^^^^^^^^^^^^
  File "/home/rvarm1/.conda/envs/torchtune-v0.1.0/lib/python3.11/site-packages/omegaconf/omegaconf.py", line 189, in load
    with io.open(os.path.abspath(file_), "r", encoding="utf-8") as f:
         ^^^^^^^^^^^^^^^^^^^^^^^^^^^^^^^^^^^^^^^^^^^^^^^^^^^^^^
FileNotFoundError: [Errno 2] No such file or directory: '/data/users/rvarm1/dev/torchtune/recipes/custom_generation_config.yaml'
