W0304 10:09:43.557000 140119180493824 torch/distributed/run.py:717] 
W0304 10:09:43.557000 140119180493824 torch/distributed/run.py:717] *****************************************
W0304 10:09:43.557000 140119180493824 torch/distributed/run.py:717] Setting OMP_NUM_THREADS environment variable for each process to be 1 in default, to avoid your system being overloaded, please further tune the variable for optimal performance in your application as needed. 
W0304 10:09:43.557000 140119180493824 torch/distributed/run.py:717] *****************************************
/home/rvarm1/.conda/envs/tune/bin/python: can't open file '/data/users/rvarm1/dev/torchtune/torchtune/_cli/recipes/full_finetune.py': [Errno 2] No such file or directory
/home/rvarm1/.conda/envs/tune/bin/python: can't open file '/data/users/rvarm1/dev/torchtune/torchtune/_cli/recipes/full_finetune.py': [Errno 2] No such file or directory
/home/rvarm1/.conda/envs/tune/bin/python: can't open file '/data/users/rvarm1/dev/torchtune/torchtune/_cli/recipes/full_finetune.py': [Errno 2] No such file or directory
/home/rvarm1/.conda/envs/tune/bin/python: can't open file '/data/users/rvarm1/dev/torchtune/torchtune/_cli/recipes/full_finetune.py': [Errno 2] No such file or directory
/home/rvarm1/.conda/envs/tune/bin/python: can't open file '/data/users/rvarm1/dev/torchtune/torchtune/_cli/recipes/full_finetune.py': [Errno 2] No such file or directory
/home/rvarm1/.conda/envs/tune/bin/python: can't open file '/data/users/rvarm1/dev/torchtune/torchtune/_cli/recipes/full_finetune.py': [Errno 2] No such file or directory
/home/rvarm1/.conda/envs/tune/bin/python: can't open file '/data/users/rvarm1/dev/torchtune/torchtune/_cli/recipes/full_finetune.py': [Errno 2] No such file or directory
/home/rvarm1/.conda/envs/tune/bin/python: can't open file '/data/users/rvarm1/dev/torchtune/torchtune/_cli/recipes/full_finetune.py': [Errno 2] No such file or directory
E0304 10:09:48.570000 140119180493824 torch/distributed/elastic/multiprocessing/api.py:669] failed (exitcode: 2) local_rank: 0 (pid: 605315) of binary: /home/rvarm1/.conda/envs/tune/bin/python
Traceback (most recent call last):
  File "/home/rvarm1/.conda/envs/tune/bin/torchrun", line 33, in <module>
    sys.exit(load_entry_point('torch==2.3.0.dev20240221', 'console_scripts', 'torchrun')())
  File "/home/rvarm1/.conda/envs/tune/lib/python3.10/site-packages/torch/distributed/elastic/multiprocessing/errors/__init__.py", line 347, in wrapper
    return f(*args, **kwargs)
  File "/home/rvarm1/.conda/envs/tune/lib/python3.10/site-packages/torch/distributed/run.py", line 834, in main
    run(args)
  File "/home/rvarm1/.conda/envs/tune/lib/python3.10/site-packages/torch/distributed/run.py", line 825, in run
    elastic_launch(
  File "/home/rvarm1/.conda/envs/tune/lib/python3.10/site-packages/torch/distributed/launcher/api.py", line 137, in __call__
    return launch_agent(self._config, self._entrypoint, list(args))
  File "/home/rvarm1/.conda/envs/tune/lib/python3.10/site-packages/torch/distributed/launcher/api.py", line 271, in launch_agent
    raise ChildFailedError(
torch.distributed.elastic.multiprocessing.errors.ChildFailedError: 
============================================================
recipes/full_finetune.py FAILED
------------------------------------------------------------
Failures:
[1]:
  time      : 2024-03-04_10:09:48
  host      : devgpu019.ftw1.facebook.com
  rank      : 1 (local_rank: 1)
  exitcode  : 2 (pid: 605316)
  error_file: <N/A>
  traceback : To enable traceback see: https://pytorch.org/docs/stable/elastic/errors.html
[2]:
  time      : 2024-03-04_10:09:48
  host      : devgpu019.ftw1.facebook.com
  rank      : 2 (local_rank: 2)
  exitcode  : 2 (pid: 605317)
  error_file: <N/A>
  traceback : To enable traceback see: https://pytorch.org/docs/stable/elastic/errors.html
[3]:
  time      : 2024-03-04_10:09:48
  host      : devgpu019.ftw1.facebook.com
  rank      : 3 (local_rank: 3)
  exitcode  : 2 (pid: 605318)
  error_file: <N/A>
  traceback : To enable traceback see: https://pytorch.org/docs/stable/elastic/errors.html
[4]:
  time      : 2024-03-04_10:09:48
  host      : devgpu019.ftw1.facebook.com
  rank      : 4 (local_rank: 4)
  exitcode  : 2 (pid: 605319)
  error_file: <N/A>
  traceback : To enable traceback see: https://pytorch.org/docs/stable/elastic/errors.html
[5]:
  time      : 2024-03-04_10:09:48
  host      : devgpu019.ftw1.facebook.com
  rank      : 5 (local_rank: 5)
  exitcode  : 2 (pid: 605320)
  error_file: <N/A>
  traceback : To enable traceback see: https://pytorch.org/docs/stable/elastic/errors.html
[6]:
  time      : 2024-03-04_10:09:48
  host      : devgpu019.ftw1.facebook.com
  rank      : 6 (local_rank: 6)
  exitcode  : 2 (pid: 605321)
  error_file: <N/A>
  traceback : To enable traceback see: https://pytorch.org/docs/stable/elastic/errors.html
[7]:
  time      : 2024-03-04_10:09:48
  host      : devgpu019.ftw1.facebook.com
  rank      : 7 (local_rank: 7)
  exitcode  : 2 (pid: 605322)
  error_file: <N/A>
  traceback : To enable traceback see: https://pytorch.org/docs/stable/elastic/errors.html
------------------------------------------------------------
Root Cause (first observed failure):
[0]:
  time      : 2024-03-04_10:09:48
  host      : devgpu019.ftw1.facebook.com
  rank      : 0 (local_rank: 0)
  exitcode  : 2 (pid: 605315)
  error_file: <N/A>
  traceback : To enable traceback see: https://pytorch.org/docs/stable/elastic/errors.html
============================================================
